<?xml version="1.0" encoding="utf-8"?>
<!-- =================================================================================== -->
<!-- |    This document was autogenerated by xacro from rbkairos_ur5e_plus.urdf.xacro  | -->
<!-- |    EDITING THIS FILE BY HAND IS NOT RECOMMENDED                                 | -->
<!-- =================================================================================== -->
<robot name="rbkairos">
  <!-- ***************** -->
  <!-- Imported elements -->
  <!-- ***************** -->
  <!-- First we import all posible elements defined in the urdf.xacro files. All these elements are defined as macro:xacros -->
  <gazebo reference="base_footprint">
    <material>Gazebo/Green</material>
  </gazebo>
  <!-- in kg-->
  <!-- in kg-->
  <!-- source en.wikipedia.org/wiki/List_of_moments_of_inertia-->
  <!-- This file unifies all sensors that can be used on simulation, defined as xacro:macros -->
  <!-- Includes -->
  <!-- Necesarry for ur_description compatible with official ur drivers-->
  <gazebo>
    <plugin filename="libgazebo_ros_control.so" name="ros_control">
      <robotParam>robot_description</robotParam>
      <controlPeriod>0.001</controlPeriod>
      <robotSimType>gazebo_ros_control/DefaultRobotHWSim</robotSimType>
      <legacyModeNS>true</legacyModeNS>
    </plugin>
  </gazebo>
  <!-- *************** -->
  <!-- Robots Elements -->
  <!-- *************** -->
  <!-- Here we create the robot elements using the xacro:macros imported at the beggining of this file -->
  <link name="robot_base_footprint">
    <visual>
      <origin rpy="0 0 0" xyz="0 0 0"/>
      <geometry>
        <box size="0.001 0.001 0.001"/>
      </geometry>
    </visual>
  </link>
  <joint name="robot_base_footprint_joint" type="fixed">
    <origin rpy="0 0 0" xyz="0 0 0.127"/>
    <!-- ${wheel_radius} property must be defined inside wheel description -->
    <parent link="robot_base_footprint"/>
    <child link="robot_base_link"/>
  </joint>
  <!-- BASE_LINK -->
  <link name="robot_base_link">
    <inertial>
      <mass value="125.0"/>
      <origin xyz="0 0 0"/>
      <inertia ixx="1.391" ixy="0.004" ixz="0.0" iyy="6.853" iyz="0.0" izz="6.125"/>
    </inertial>
    <visual>
      <origin rpy="0 0 0" xyz="0 0 0"/>
      <geometry>
        <mesh filename="package://summit_xl_description/meshes/bases/xls/summit_xlsk_plus.stl"/>
      </geometry>
      <material name="black">
        <color rgba="0.0 0.0 0.0 1"/>
      </material>
    </visual>
    <collision>
      <origin rpy="0 0 0 " xyz="0 0 0"/>
      <geometry>
        <mesh filename="package://summit_xl_description/meshes/bases/xls/summit_xlsk_plus.dae"/>
      </geometry>
    </collision>
  </link>
  <gazebo reference="robot_base_link">
    <material>Gazebo/Black</material>
  </gazebo>
  <!-- CHAPAS INOX TAPAS -->
  <link name="robot_base_chapa">
    <visual>
      <origin rpy="0 0 0" xyz="0 0 0"/>
      <geometry>
        <mesh filename="package://summit_xl_description/meshes/bases/xls/summit_xls_chapas_inox_tapas.stl"/>
      </geometry>
      <material name="darkgrey">
        <color rgba="0.5 0.5 0.5 1"/>
      </material>
    </visual>
  </link>
  <joint name="robot_base_tapa_joint" type="fixed">
    <origin rpy="0 0 0" xyz="0.0 0 0.38062"/>
    <parent link="robot_base_link"/>
    <child link="robot_base_chapa"/>
  </joint>
  <!-- LOGO ROBOTNIK IZQUIERDO -->
  <link name="robot_base_logo_left">
    <visual>
      <origin rpy="0 0 0" xyz="0 0 0"/>
      <geometry>
        <mesh filename="package://summit_xl_description/meshes/bases/xls/robotnik_logo_chasis.stl"/>
      </geometry>
      <material name="darkgrey">
        <color rgba="0.5 0.5 0.5 1"/>
      </material>
    </visual>
  </link>
  <joint name="robot_base_logo_left_joint" type="fixed">
    <origin rpy="0 0 0" xyz="0.0 0.28931 0.29062"/>
    <parent link="robot_base_link"/>
    <child link="robot_base_logo_left"/>
  </joint>
  <!-- LOGO ROBOTNIK DERECHO -->
  <link name="robot_base_logo_right">
    <visual>
      <origin rpy="0 0 0" xyz="0 0 0"/>
      <geometry>
        <mesh filename="package://summit_xl_description/meshes/bases/xls/robotnik_logo_chasis.stl"/>
      </geometry>
      <material name="darkgrey">
        <color rgba="0.5 0.5 0.5 1"/>
      </material>
    </visual>
  </link>
  <joint name="robot_base_logo_right_joint" type="fixed">
    <origin rpy="0 0 3.14159265359" xyz="0.0 -0.28931 0.29062"/>
    <parent link="robot_base_link"/>
    <child link="robot_base_logo_right"/>
  </joint>
  <!-- LOGO ROBOTNIK FRONTAL -->
  <link name="robot_base_logo_front">
    <visual>
      <origin rpy="0 0 0" xyz="0 0 0"/>
      <geometry>
        <mesh filename="package://summit_xl_description/meshes/bases/xls/robotnik_logo_chasis.stl"/>
      </geometry>
      <material name="darkgrey">
        <color rgba="0.5 0.5 0.5 1"/>
      </material>
    </visual>
  </link>
  <joint name="robot_base_logo_front_joint" type="fixed">
    <origin rpy="0 0 -1.57079632679" xyz="0.345 0.0 0.0"/>
    <parent link="robot_base_link"/>
    <child link="robot_base_logo_front"/>
  </joint>
  <!-- LOGO ROBOTNIK TRASERO -->
  <link name="robot_base_logo_rear">
    <visual>
      <origin rpy="0 0 0" xyz="0 0 0"/>
      <geometry>
        <mesh filename="package://summit_xl_description/meshes/bases/xls/robotnik_logo_chasis.stl"/>
      </geometry>
      <material name="darkgrey">
        <color rgba="0.5 0.5 0.5 1"/>
      </material>
    </visual>
  </link>
  <joint name="robot_base_logo_rear_joint" type="fixed">
    <origin rpy="0 0 1.57079632679" xyz="-0.345 0.0 0.0"/>
    <parent link="robot_base_link"/>
    <child link="robot_base_logo_rear"/>
  </joint>
  <!-- DOCKING CONTACT -->
  <link name="robot_base_docking_contact">
    </link>
  <joint name="robot_base_docking_joint" type="fixed">
    <origin rpy="0 0 0" xyz="0.35 0 0.09"/>
    <parent link="robot_base_link"/>
    <child link="robot_base_docking_contact"/>
  </joint>
  <joint name="robot_front_right_wheel_joint" type="continuous">
    <parent link="robot_base_link"/>
    <child link="robot_front_right_wheel_link"/>
    <origin rpy="0 0 0" xyz="0.21528 -0.269 0.0"/>
    <axis rpy="0 0 0" xyz="0 1 0"/>
    <limit effort="100" velocity="100"/>
    <joint_properties damping="0.0" friction="0.0"/>
  </joint>
  <link name="robot_front_right_wheel_link">
    <visual>
      <origin rpy="0 0 0" xyz="0 0 0"/>
      <geometry>
        <mesh filename="package://summit_xl_description/meshes/wheels/omni_wheel_2.dae"/>
      </geometry>
      <material name="darkgrey">
        <color rgba="0.2 0.2 0.2 1"/>
      </material>
    </visual>
    <collision>
      <origin rpy="1.57079632679 0 0" xyz="0 0 0"/>
      <geometry>
        <!--sphere radius="${omni_wheel_radius}" /-->
        <!--
          <xacro:if value="${reflect}">
              <mesh filename="package://summit_xl_description/meshes/wheels/omni_wheel_1.dae" />
          </xacro:if>
          <xacro:unless value="${reflect}">
              <mesh filename="package://summit_xl_description/meshes/wheels/omni_wheel_2.dae" />
					</xacro:unless>
-->
        <cylinder length="0.087" radius="0.127"/>
      </geometry>
    </collision>
    <inertial>
      <mass value="6.5"/>
      <origin xyz="0 0 0"/>
      <inertia ixx="0.0303095" ixy="0" ixz="0" iyy="0.05241925" iyz="0" izz="0.0303095"/>
    </inertial>
  </link>
  <!-- Transmission is important to link the joints and the controller (see summit_xl_control/config/summit_xl_control.yaml)-->
  <transmission name="robot_front_right_wheel_joint_trans">
    <type>transmission_interface/SimpleTransmission</type>
    <joint name="robot_front_right_wheel_joint">
      <hardwareInterface>hardware_interface/VelocityJointInterface</hardwareInterface>
    </joint>
    <actuator name="robot_front_right_wheel_joint_motor">
      <mechanicalReduction>1</mechanicalReduction>
    </actuator>
  </transmission>
  <gazebo reference="robot_front_right_wheel_link">
    <mu1 value="0.0"/>
    <mu2 value="0.0"/>
    <kp value="10000000.0"/>
    <kd value="1.0"/>
    <fdir1 value="1 0 0"/>
    <turnGravityOff>false</turnGravityOff>
  </gazebo>
  <joint name="robot_front_left_wheel_joint" type="continuous">
    <parent link="robot_base_link"/>
    <child link="robot_front_left_wheel_link"/>
    <origin rpy="0 0 0" xyz="0.21528 0.269 0.0"/>
    <axis rpy="0 0 0" xyz="0 1 0"/>
    <limit effort="100" velocity="100"/>
    <joint_properties damping="0.0" friction="0.0"/>
  </joint>
  <link name="robot_front_left_wheel_link">
    <visual>
      <origin rpy="0 0 0" xyz="0 0 0"/>
      <geometry>
        <mesh filename="package://summit_xl_description/meshes/wheels/omni_wheel_1.dae"/>
      </geometry>
      <material name="darkgrey">
        <color rgba="0.2 0.2 0.2 1"/>
      </material>
    </visual>
    <collision>
      <origin rpy="1.57079632679 0 0" xyz="0 0 0"/>
      <geometry>
        <!--sphere radius="${omni_wheel_radius}" /-->
        <!--
          <xacro:if value="${reflect}">
              <mesh filename="package://summit_xl_description/meshes/wheels/omni_wheel_1.dae" />
          </xacro:if>
          <xacro:unless value="${reflect}">
              <mesh filename="package://summit_xl_description/meshes/wheels/omni_wheel_2.dae" />
					</xacro:unless>
-->
        <cylinder length="0.087" radius="0.127"/>
      </geometry>
    </collision>
    <inertial>
      <mass value="6.5"/>
      <origin xyz="0 0 0"/>
      <inertia ixx="0.0303095" ixy="0" ixz="0" iyy="0.05241925" iyz="0" izz="0.0303095"/>
    </inertial>
  </link>
  <!-- Transmission is important to link the joints and the controller (see summit_xl_control/config/summit_xl_control.yaml)-->
  <transmission name="robot_front_left_wheel_joint_trans">
    <type>transmission_interface/SimpleTransmission</type>
    <joint name="robot_front_left_wheel_joint">
      <hardwareInterface>hardware_interface/VelocityJointInterface</hardwareInterface>
    </joint>
    <actuator name="robot_front_left_wheel_joint_motor">
      <mechanicalReduction>1</mechanicalReduction>
    </actuator>
  </transmission>
  <gazebo reference="robot_front_left_wheel_link">
    <mu1 value="0.0"/>
    <mu2 value="0.0"/>
    <kp value="10000000.0"/>
    <kd value="1.0"/>
    <fdir1 value="1 0 0"/>
    <turnGravityOff>false</turnGravityOff>
  </gazebo>
  <joint name="robot_back_left_wheel_joint" type="continuous">
    <parent link="robot_base_link"/>
    <child link="robot_back_left_wheel_link"/>
    <origin rpy="0 0 0" xyz="-0.21528 0.269 0.0"/>
    <axis rpy="0 0 0" xyz="0 1 0"/>
    <limit effort="100" velocity="100"/>
    <joint_properties damping="0.0" friction="0.0"/>
  </joint>
  <link name="robot_back_left_wheel_link">
    <visual>
      <origin rpy="0 0 0" xyz="0 0 0"/>
      <geometry>
        <mesh filename="package://summit_xl_description/meshes/wheels/omni_wheel_1.dae"/>
      </geometry>
      <material name="darkgrey">
        <color rgba="0.2 0.2 0.2 1"/>
      </material>
    </visual>
    <collision>
      <origin rpy="1.57079632679 0 0" xyz="0 0 0"/>
      <geometry>
        <!--sphere radius="${omni_wheel_radius}" /-->
        <!--
          <xacro:if value="${reflect}">
              <mesh filename="package://summit_xl_description/meshes/wheels/omni_wheel_1.dae" />
          </xacro:if>
          <xacro:unless value="${reflect}">
              <mesh filename="package://summit_xl_description/meshes/wheels/omni_wheel_2.dae" />
					</xacro:unless>
-->
        <cylinder length="0.087" radius="0.127"/>
      </geometry>
    </collision>
    <inertial>
      <mass value="6.5"/>
      <origin xyz="0 0 0"/>
      <inertia ixx="0.0303095" ixy="0" ixz="0" iyy="0.05241925" iyz="0" izz="0.0303095"/>
    </inertial>
  </link>
  <!-- Transmission is important to link the joints and the controller (see summit_xl_control/config/summit_xl_control.yaml)-->
  <transmission name="robot_back_left_wheel_joint_trans">
    <type>transmission_interface/SimpleTransmission</type>
    <joint name="robot_back_left_wheel_joint">
      <hardwareInterface>hardware_interface/VelocityJointInterface</hardwareInterface>
    </joint>
    <actuator name="robot_back_left_wheel_joint_motor">
      <mechanicalReduction>1</mechanicalReduction>
    </actuator>
  </transmission>
  <gazebo reference="robot_back_left_wheel_link">
    <mu1 value="0.0"/>
    <mu2 value="0.0"/>
    <kp value="10000000.0"/>
    <kd value="1.0"/>
    <fdir1 value="1 0 0"/>
    <turnGravityOff>false</turnGravityOff>
  </gazebo>
  <joint name="robot_back_right_wheel_joint" type="continuous">
    <parent link="robot_base_link"/>
    <child link="robot_back_right_wheel_link"/>
    <origin rpy="0 0 0" xyz="-0.21528 -0.269 0.0"/>
    <axis rpy="0 0 0" xyz="0 1 0"/>
    <limit effort="100" velocity="100"/>
    <joint_properties damping="0.0" friction="0.0"/>
  </joint>
  <link name="robot_back_right_wheel_link">
    <visual>
      <origin rpy="0 0 0" xyz="0 0 0"/>
      <geometry>
        <mesh filename="package://summit_xl_description/meshes/wheels/omni_wheel_2.dae"/>
      </geometry>
      <material name="darkgrey">
        <color rgba="0.2 0.2 0.2 1"/>
      </material>
    </visual>
    <collision>
      <origin rpy="1.57079632679 0 0" xyz="0 0 0"/>
      <geometry>
        <!--sphere radius="${omni_wheel_radius}" /-->
        <!--
          <xacro:if value="${reflect}">
              <mesh filename="package://summit_xl_description/meshes/wheels/omni_wheel_1.dae" />
          </xacro:if>
          <xacro:unless value="${reflect}">
              <mesh filename="package://summit_xl_description/meshes/wheels/omni_wheel_2.dae" />
					</xacro:unless>
-->
        <cylinder length="0.087" radius="0.127"/>
      </geometry>
    </collision>
    <inertial>
      <mass value="6.5"/>
      <origin xyz="0 0 0"/>
      <inertia ixx="0.0303095" ixy="0" ixz="0" iyy="0.05241925" iyz="0" izz="0.0303095"/>
    </inertial>
  </link>
  <!-- Transmission is important to link the joints and the controller (see summit_xl_control/config/summit_xl_control.yaml)-->
  <transmission name="robot_back_right_wheel_joint_trans">
    <type>transmission_interface/SimpleTransmission</type>
    <joint name="robot_back_right_wheel_joint">
      <hardwareInterface>hardware_interface/VelocityJointInterface</hardwareInterface>
    </joint>
    <actuator name="robot_back_right_wheel_joint_motor">
      <mechanicalReduction>1</mechanicalReduction>
    </actuator>
  </transmission>
  <gazebo reference="robot_back_right_wheel_link">
    <mu1 value="0.0"/>
    <mu2 value="0.0"/>
    <kp value="10000000.0"/>
    <kd value="1.0"/>
    <fdir1 value="1 0 0"/>
    <turnGravityOff>false</turnGravityOff>
  </gazebo>
  <!-- measured from model -->
  <!-- link lengths used in model -->
  <!-- manually measured -->
  <link name="robot_arm_base_link">
    <visual>
      <origin rpy="0 0 3.14159265359" xyz="0 0 0"/>
      <geometry>
        <mesh filename="package://ur_e_description/meshes/ur5e/visual/base.dae"/>
      </geometry>
      <material name="LightGrey">
        <color rgba="0.7 0.7 0.7 1.0"/>
      </material>
    </visual>
    <collision>
      <origin rpy="0 0 3.14159265359" xyz="0 0 0"/>
      <geometry>
        <mesh filename="package://ur_e_description/meshes/ur5e/collision/base.stl"/>
      </geometry>
    </collision>
    <inertial>
      <mass value="4.0"/>
      <origin rpy="0 0 0" xyz="0.0 0.0 0.0"/>
      <inertia ixx="0.00443333156" ixy="0.0" ixz="0.0" iyy="0.00443333156" iyz="0.0" izz="0.0072"/>
    </inertial>
  </link>
  <joint name="robot_arm_shoulder_pan_joint" type="revolute">
    <parent link="robot_arm_base_link"/>
    <child link="robot_arm_shoulder_link"/>
    <origin rpy="0 0 3.14159261339" xyz="0 0 0.162760406357"/>
    <axis xyz="0 0 1"/>
    <limit effort="150.0" lower="-3.14159265359" upper="3.14159265359" velocity="3.14"/>
    <dynamics damping="0.0" friction="0.0"/>
  </joint>
  <link name="robot_arm_shoulder_link">
    <visual>
      <origin rpy="0 0 3.14159265359" xyz="0 0 0"/>
      <geometry>
        <mesh filename="package://ur_e_description/meshes/ur5e/visual/shoulder.dae"/>
      </geometry>
      <material name="LightGrey">
        <color rgba="0.7 0.7 0.7 1.0"/>
      </material>
    </visual>
    <collision>
      <origin rpy="0 0 3.14159265359" xyz="0 0 0"/>
      <geometry>
        <mesh filename="package://ur_e_description/meshes/ur5e/collision/shoulder.stl"/>
      </geometry>
    </collision>
    <inertial>
      <mass value="3.7"/>
      <origin rpy="0 0 0" xyz="0.0 0.0 0.0"/>
      <inertia ixx="0.010267495893" ixy="0.0" ixz="0.0" iyy="0.010267495893" iyz="0.0" izz="0.00666"/>
    </inertial>
  </link>
  <joint name="robot_arm_shoulder_lift_joint" type="revolute">
    <parent link="robot_arm_shoulder_link"/>
    <child link="robot_arm_upper_arm_link"/>
    <origin rpy="1.57111058039 0 -4.05740805707e-06" xyz="0.000270038585262 0 0"/>
    <axis xyz="0 0 1"/>
    <limit effort="150.0" lower="-3.14159265359" upper="3.14159265359" velocity="3.14"/>
    <dynamics damping="0.0" friction="0.0"/>
  </joint>
  <link name="robot_arm_upper_arm_link">
    <visual>
      <origin rpy="1.57079632679 0 -1.57079632679" xyz="0 0 0.138"/>
      <geometry>
        <mesh filename="package://ur_e_description/meshes/ur5e/visual/upperarm.dae"/>
      </geometry>
      <material name="LightGrey">
        <color rgba="0.7 0.7 0.7 1.0"/>
      </material>
    </visual>
    <collision>
      <origin rpy="1.57079632679 0 -1.57079632679" xyz="0 0 0.138"/>
      <geometry>
        <mesh filename="package://ur_e_description/meshes/ur5e/collision/upperarm.stl"/>
      </geometry>
    </collision>
    <inertial>
      <mass value="8.393"/>
      <origin rpy="0 1.57079632679 0" xyz="-0.212595378066 0.0 0.138"/>
      <inertia ixx="0.138248167133" ixy="0.0" ixz="0.0" iyy="0.138248167133" iyz="0.0" izz="0.0236053125"/>
    </inertial>
  </link>
  <joint name="robot_arm_elbow_joint" type="revolute">
    <parent link="robot_arm_upper_arm_link"/>
    <child link="robot_arm_forearm_link"/>
    <origin rpy="0.00105070338239 -0.000582131310581 -7.19055651207e-07" xyz="-0.425190756132 0 0"/>
    <axis xyz="0 0 1"/>
    <limit effort="150.0" lower="-3.14159265359" upper="3.14159265359" velocity="3.14"/>
    <dynamics damping="0.0" friction="0.0"/>
  </joint>
  <link name="robot_arm_forearm_link">
    <visual>
      <origin rpy="1.57079632679 0 -1.57079632679" xyz="0 0 0.007"/>
      <geometry>
        <mesh filename="package://ur_e_description/meshes/ur5e/visual/forearm.dae"/>
      </geometry>
      <material name="LightGrey">
        <color rgba="0.7 0.7 0.7 1.0"/>
      </material>
    </visual>
    <collision>
      <origin rpy="1.57079632679 0 -1.57079632679" xyz="0 0 0.007"/>
      <geometry>
        <mesh filename="package://ur_e_description/meshes/ur5e/collision/forearm.stl"/>
      </geometry>
    </collision>
    <inertial>
      <mass value="2.275"/>
      <origin rpy="0 1.57079632679 0" xyz="-0.212595378066 0.0 0.007"/>
      <inertia ixx="0.0323868468787" ixy="0.0" ixz="0.0" iyy="0.0323868468787" iyz="0.0" izz="0.0063984375"/>
    </inertial>
  </link>
  <joint name="robot_arm_wrist_1_joint" type="revolute">
    <parent link="robot_arm_forearm_link"/>
    <child link="robot_arm_wrist_1_link"/>
    <origin rpy="0.00579767922874 0.000666877322099 -4.18085587714e-06" xyz="-0.392373276527 -0.000774971902154 0.133667833023"/>
    <axis xyz="0 0 1"/>
    <limit effort="28.0" lower="-3.14159265359" upper="3.14159265359" velocity="6.28"/>
    <dynamics damping="0.0" friction="0.0"/>
  </joint>
  <link name="robot_arm_wrist_1_link">
    <visual>
      <origin rpy="1.57079632679 0 0" xyz="0 0 -0.127"/>
      <geometry>
        <mesh filename="package://ur_e_description/meshes/ur5e/visual/wrist1.dae"/>
      </geometry>
      <material name="LightGrey">
        <color rgba="0.7 0.7 0.7 1.0"/>
      </material>
    </visual>
    <collision>
      <origin rpy="1.57079632679 0 0" xyz="0 0 -0.127"/>
      <geometry>
        <mesh filename="package://ur_e_description/meshes/ur5e/collision/wrist1.stl"/>
      </geometry>
    </collision>
    <inertial>
      <mass value="1.219"/>
      <origin rpy="0 0 0" xyz="0.0 0.0 0.0"/>
      <inertia ixx="0.0027239784339" ixy="0.0" ixz="0.0" iyy="0.0027239784339" iyz="0.0" izz="0.0034284375"/>
    </inertial>
  </link>
  <joint name="robot_arm_wrist_2_joint" type="revolute">
    <parent link="robot_arm_wrist_1_link"/>
    <child link="robot_arm_wrist_2_link"/>
    <origin rpy="1.5697812866 0 -8.14211991287e-07" xyz="1.95486751335e-05 -0.0997006564869 0.000101200208252"/>
    <axis xyz="0 0 1"/>
    <limit effort="28.0" lower="-3.14159265359" upper="3.14159265359" velocity="6.28"/>
    <dynamics damping="0.0" friction="0.0"/>
  </joint>
  <link name="robot_arm_wrist_2_link">
    <visual>
      <origin rpy="0 0 0" xyz="0 0 -0.0997"/>
      <geometry>
        <mesh filename="package://ur_e_description/meshes/ur5e/visual/wrist2.dae"/>
      </geometry>
      <material name="LightGrey">
        <color rgba="0.7 0.7 0.7 1.0"/>
      </material>
    </visual>
    <collision>
      <origin rpy="0 0 0" xyz="0 0 -0.0997"/>
      <geometry>
        <mesh filename="package://ur_e_description/meshes/ur5e/collision/wrist2.stl"/>
      </geometry>
    </collision>
    <inertial>
      <mass value="1.219"/>
      <origin rpy="0 0 0" xyz="0.0 0.0 0.0"/>
      <inertia ixx="0.0027218845252" ixy="0.0" ixz="0.0" iyy="0.0027218845252" iyz="0.0" izz="0.0034284375"/>
    </inertial>
  </link>
  <joint name="robot_arm_wrist_3_joint" type="revolute">
    <parent link="robot_arm_wrist_2_link"/>
    <child link="robot_arm_wrist_3_link"/>
    <origin rpy="1.57154621021 3.14159265359 -3.14159228866" xyz="-4.00397444109e-05 0.0995972297642 7.46863249879e-05"/>
    <axis xyz="0 0 1"/>
    <limit effort="28.0" lower="-3.14159265359" upper="3.14159265359" velocity="6.28"/>
    <dynamics damping="0.0" friction="0.0"/>
  </joint>
  <link name="robot_arm_wrist_3_link">
    <visual>
      <origin rpy="1.57079632679 0 0" xyz="0 0 -0.0989"/>
      <geometry>
        <mesh filename="package://ur_e_description/meshes/ur5e/visual/wrist3.dae"/>
      </geometry>
      <material name="LightGrey">
        <color rgba="0.7 0.7 0.7 1.0"/>
      </material>
    </visual>
    <collision>
      <origin rpy="1.57079632679 0 0" xyz="0 0 -0.0989"/>
      <geometry>
        <mesh filename="package://ur_e_description/meshes/ur5e/collision/wrist3.stl"/>
      </geometry>
    </collision>
    <inertial>
      <mass value="0.1879"/>
      <origin rpy="0 0 0" xyz="0.0 0.0 -0.025"/>
      <inertia ixx="0.000134270154625" ixy="0.0" ixz="0.0" iyy="0.000134270154625" iyz="0.0" izz="0.00019024875"/>
    </inertial>
  </link>
  <joint name="robot_arm_ee_fixed_joint" type="fixed">
    <parent link="robot_arm_wrist_3_link"/>
    <child link="robot_arm_ee_link"/>
    <origin rpy="0.0 -1.57079632679 1.57079632679" xyz="0.0 0.0 0.0"/>
  </joint>
  <link name="robot_arm_ee_link">
    <collision>
      <geometry>
        <box size="0.01 0.01 0.01"/>
      </geometry>
      <origin rpy="0 0 0" xyz="-0.01 0 0"/>
    </collision>
  </link>
  <transmission name="robot_arm_shoulder_pan_trans">
    <type>transmission_interface/SimpleTransmission</type>
    <joint name="robot_arm_shoulder_pan_joint">
      <hardwareInterface>hardware_interface/PositionJointInterface</hardwareInterface>
    </joint>
    <actuator name="robot_arm_shoulder_pan_motor">
      <mechanicalReduction>1</mechanicalReduction>
    </actuator>
  </transmission>
  <transmission name="robot_arm_shoulder_lift_trans">
    <type>transmission_interface/SimpleTransmission</type>
    <joint name="robot_arm_shoulder_lift_joint">
      <hardwareInterface>hardware_interface/PositionJointInterface</hardwareInterface>
    </joint>
    <actuator name="robot_arm_shoulder_lift_motor">
      <mechanicalReduction>1</mechanicalReduction>
    </actuator>
  </transmission>
  <transmission name="robot_arm_elbow_trans">
    <type>transmission_interface/SimpleTransmission</type>
    <joint name="robot_arm_elbow_joint">
      <hardwareInterface>hardware_interface/PositionJointInterface</hardwareInterface>
    </joint>
    <actuator name="robot_arm_elbow_motor">
      <mechanicalReduction>1</mechanicalReduction>
    </actuator>
  </transmission>
  <transmission name="robot_arm_wrist_1_trans">
    <type>transmission_interface/SimpleTransmission</type>
    <joint name="robot_arm_wrist_1_joint">
      <hardwareInterface>hardware_interface/PositionJointInterface</hardwareInterface>
    </joint>
    <actuator name="robot_arm_wrist_1_motor">
      <mechanicalReduction>1</mechanicalReduction>
    </actuator>
  </transmission>
  <transmission name="robot_arm_wrist_2_trans">
    <type>transmission_interface/SimpleTransmission</type>
    <joint name="robot_arm_wrist_2_joint">
      <hardwareInterface>hardware_interface/PositionJointInterface</hardwareInterface>
    </joint>
    <actuator name="robot_arm_wrist_2_motor">
      <mechanicalReduction>1</mechanicalReduction>
    </actuator>
  </transmission>
  <transmission name="robot_arm_wrist_3_trans">
    <type>transmission_interface/SimpleTransmission</type>
    <joint name="robot_arm_wrist_3_joint">
      <hardwareInterface>hardware_interface/PositionJointInterface</hardwareInterface>
    </joint>
    <actuator name="robot_arm_wrist_3_motor">
      <mechanicalReduction>1</mechanicalReduction>
    </actuator>
  </transmission>
  <gazebo reference="robot_arm_shoulder_link">
    <selfCollide>true</selfCollide>
  </gazebo>
  <gazebo reference="robot_arm_upper_arm_link">
    <selfCollide>true</selfCollide>
  </gazebo>
  <gazebo reference="robot_arm_forearm_link">
    <selfCollide>true</selfCollide>
  </gazebo>
  <gazebo reference="robot_arm_wrist_1_link">
    <selfCollide>true</selfCollide>
  </gazebo>
  <gazebo reference="robot_arm_wrist_3_link">
    <selfCollide>true</selfCollide>
  </gazebo>
  <gazebo reference="robot_arm_wrist_2_link">
    <selfCollide>true</selfCollide>
  </gazebo>
  <gazebo reference="robot_arm_ee_link">
    <selfCollide>true</selfCollide>
  </gazebo>
  <!-- ROS base_link to UR 'Base' Coordinates transform -->
  <link name="robot_arm_base"/>
  <joint name="robot_arm_base_link-base_fixed_joint" type="fixed">
    <!-- NOTE: this rotation is only needed as long as base_link itself is
                 not corrected wrt the real robot (ie: rotated over 180
                 degrees)
      -->
    <origin rpy="0 0 -3.14159265359" xyz="0 0 0"/>
    <parent link="robot_arm_base_link"/>
    <child link="robot_arm_base"/>
  </joint>
  <!-- Frame coincident with all-zeros TCP on UR controller -->
  <link name="robot_arm_tool0"/>
  <joint name="robot_arm_wrist_3_link-tool0_fixed_joint" type="fixed">
    <origin rpy="0 0 0" xyz="0 0 0"/>
    <parent link="robot_arm_wrist_3_link"/>
    <child link="robot_arm_tool0"/>
  </joint>
  <joint name="robot_arm_base_joint" type="fixed">
    <origin rpy="0 0 3.141516" xyz="0.15887 0 0.56162"/>
    <parent link="robot_base_link"/>
    <child link="robot_arm_base_link"/>
  </joint>
  <joint name="robot_imu_joint" type="fixed">
    <axis xyz="1 0 0"/>
    <!--origin xyz="0 0 0.2825"/-->
    <origin rpy="0 0 0" xyz="0.127 -0.129 0.212"/>
    <parent link="robot_base_link"/>
    <child link="robot_imu_link"/>
  </joint>
  <link name="robot_imu_link">
    <inertial>
      <origin rpy="0 0 0" xyz="0.0 0 0.01"/>
      <mass value="0.05"/>
      <inertia ixx="3.33333333333e-06" ixy="0" ixz="0" iyy="3.33333333333e-06" iyz="0" izz="3.33333333333e-06"/>
    </inertial>
    <visual>
      <origin rpy="0 0 0" xyz="0 0 0"/>
      <geometry>
        <box size="0.001 0.001 0.001"/>
      </geometry>
    </visual>
    <collision>
      <origin rpy="0 0 0" xyz="0 0 0"/>
      <geometry>
        <box size=".001 .001 .001"/>
      </geometry>
    </collision>
  </link>
  <gazebo>
    <plugin filename="libhector_gazebo_ros_imu.so" name="robot_imu_controller">
      <alwaysOn>true</alwaysOn>
      <topicName>imu/data</topicName>
      <serviceName>robot_imuimu/service</serviceName>
      <bodyName>robot_imu_link</bodyName>
      <frameId>robot_imu_link</frameId>
      <updateRate>50.0</updateRate>
      <gaussianNoise>0.00</gaussianNoise>
      <yawOffset>0.0</yawOffset>
      <yawDrift>0.0</yawDrift>
      <yawGaussianNoise>0.0</yawGaussianNoise>
      <!-- angular velocities parameters -->
      <rateOffset>0.0 0.0 0.0</rateOffset>
      <rateDrift>0.0 0.0 0.0</rateDrift>
      <rateGaussianNoise>0.0 0.0 0.0</rateGaussianNoise>
      <!-- linear accelerations parameters -->
      <accelOffset>0.0 0.0 0.0</accelOffset>
      <accelDrift>0.0 0.0 0.0</accelDrift>
      <accelGaussianNoise>0.0 0.0 0.0</accelGaussianNoise>
    </plugin>
  </gazebo>
  <joint name="robot_front_laser_base_joint" type="fixed">
    <origin rpy="0 -3.14159265359 2.35619449019" xyz="0.28933 -0.21176 0.17172"/>
    <parent link="robot_base_link"/>
    <child link="robot_front_laser_base_link"/>
  </joint>
  <link name="robot_front_laser_base_link">
    <collision>
      <origin rpy="0 0 0" xyz="0 0 0.0"/>
      <geometry>
        <box size="0.010 0.010 0.010"/>
      </geometry>
    </collision>
    <visual>
      <origin rpy="0 0 0" xyz="0 0 0.0"/>
      <geometry>
        <mesh filename="package://robotnik_sensors/meshes/hokuyo_ust_10lx.dae"/>
      </geometry>
    </visual>
    <inertial>
      <origin rpy="0 0 0" xyz="0.0 0 0.035"/>
      <mass value="0.130"/>
      <inertia ixx="8.01666666667e-05" ixy="0" ixz="0" iyy="8.01666666667e-05" iyz="0" izz="5.41666666667e-05"/>
    </inertial>
  </link>
  <joint name="robot_front_laser_joint" type="fixed">
    <origin rpy="0 0 0" xyz="0 0 0.0474"/>
    <parent link="robot_front_laser_base_link"/>
    <child link="robot_front_laser_link"/>
  </joint>
  <link name="robot_front_laser_link">
    </link>
  <gazebo reference="robot_front_laser_link">
    <sensor name="robot_front_laser_sensor" type="gpu_ray">
      <pose>0 0 0 0 0 0</pose>
      <visualize>false</visualize>
      <update_rate>40</update_rate>
      <ray>
        <scan>
          <horizontal>
            <samples>1081</samples>
            <resolution>1</resolution>
            <min_angle>-2.3562</min_angle>
            <max_angle>2.3562</max_angle>
          </horizontal>
        </scan>
        <range>
          <min>0.06</min>
          <max>10.0</max>
          <!-- resolution>0.004363323</resolution -->
          <resolution>0.004359297</resolution>
          <!-- resolution>0.001</resolution -->
        </range>
        <noise>
          <type>gaussian</type>
          <mean>0.0</mean>
          <stddev>0.01</stddev>
        </noise>
      </ray>
      <plugin filename="libgazebo_ros_gpu_laser.so" name="robot_front_laser_controller">
        <topicName>front_laser/scan</topicName>
        <frameName>/robot_front_laser_link</frameName>
      </plugin>
    </sensor>
  </gazebo>
  <joint name="robot_rear_laser_base_joint" type="fixed">
    <origin rpy="0 -3.14159265359 -0.785398163397" xyz="-0.28933 0.21176 0.17172"/>
    <parent link="robot_base_link"/>
    <child link="robot_rear_laser_base_link"/>
  </joint>
  <link name="robot_rear_laser_base_link">
    <collision>
      <origin rpy="0 0 0" xyz="0 0 0.0"/>
      <geometry>
        <box size="0.010 0.010 0.010"/>
      </geometry>
    </collision>
    <visual>
      <origin rpy="0 0 0" xyz="0 0 0.0"/>
      <geometry>
        <mesh filename="package://robotnik_sensors/meshes/hokuyo_ust_10lx.dae"/>
      </geometry>
    </visual>
    <inertial>
      <origin rpy="0 0 0" xyz="0.0 0 0.035"/>
      <mass value="0.130"/>
      <inertia ixx="8.01666666667e-05" ixy="0" ixz="0" iyy="8.01666666667e-05" iyz="0" izz="5.41666666667e-05"/>
    </inertial>
  </link>
  <joint name="robot_rear_laser_joint" type="fixed">
    <origin rpy="0 0 0" xyz="0 0 0.0474"/>
    <parent link="robot_rear_laser_base_link"/>
    <child link="robot_rear_laser_link"/>
  </joint>
  <link name="robot_rear_laser_link">
    </link>
  <gazebo reference="robot_rear_laser_link">
    <sensor name="robot_rear_laser_sensor" type="gpu_ray">
      <pose>0 0 0 0 0 0</pose>
      <visualize>false</visualize>
      <update_rate>40</update_rate>
      <ray>
        <scan>
          <horizontal>
            <samples>1081</samples>
            <resolution>1</resolution>
            <min_angle>-2.3562</min_angle>
            <max_angle>2.3562</max_angle>
          </horizontal>
        </scan>
        <range>
          <min>0.06</min>
          <max>10.0</max>
          <!-- resolution>0.004363323</resolution -->
          <resolution>0.004359297</resolution>
          <!-- resolution>0.001</resolution -->
        </range>
        <noise>
          <type>gaussian</type>
          <mean>0.0</mean>
          <stddev>0.01</stddev>
        </noise>
      </ray>
      <plugin filename="libgazebo_ros_gpu_laser.so" name="robot_rear_laser_controller">
        <topicName>rear_laser/scan</topicName>
        <frameName>/robot_rear_laser_link</frameName>
      </plugin>
    </sensor>
  </gazebo>
  <joint name="robot_front_rgbd_camera_joint" type="fixed">
    <origin rpy="0 0 0" xyz="0.3381 0.0 0.25062"/>
    <parent link="robot_base_link"/>
    <child link="robot_front_rgbd_camera_link"/>
  </joint>
  <link name="robot_front_rgbd_camera_link">
    <visual>
      <origin rpy="0 0 0" xyz="0 0 0"/>
      <geometry>
        <mesh filename="package://robotnik_sensors/meshes/orbbec_astra.dae"/>
      </geometry>
    </visual>
    <collision>
      <geometry>
        <mesh filename="package://robotnik_sensors/meshes/orbbec_astra.dae"/>
      </geometry>
    </collision>
    <inertial>
      <mass value="0.001"/>
      <origin xyz="0.0 0.0 0.0"/>
      <inertia ixx="2.34375e-06" ixy="0" ixz="0" iyy="2.08333333333e-07" iyz="0" izz="2.40208333333e-06"/>
    </inertial>
  </link>
  <joint name="robot_front_rgbd_camera_rgb_joint" type="fixed">
    <origin rpy="0.0 0.0 0.0" xyz="0.0 0.0125 0.0150"/>
    <parent link="robot_front_rgbd_camera_link"/>
    <child link="robot_front_rgbd_camera_rgb_frame"/>
  </joint>
  <link name="robot_front_rgbd_camera_rgb_frame">
    <inertial>
      <mass value="0.297"/>
      <origin xyz="-0.02 -0.0125 0.0"/>
      <inertia ixx="0.00069609375" ixy="0" ixz="0" iyy="6.1875e-05" iyz="0" izz="0.00071341875"/>
    </inertial>
  </link>
  <joint name="robot_front_rgbd_camera_rgb_optical_joint" type="fixed">
    <origin rpy="-1.57079632679 0 -1.57079632679" xyz="0.0 0.0 0.0"/>
    <parent link="robot_front_rgbd_camera_rgb_frame"/>
    <child link="robot_front_rgbd_camera_rgb_optical_frame"/>
  </joint>
  <link name="robot_front_rgbd_camera_rgb_optical_frame">
    <inertial>
      <mass value="0.001"/>
      <origin rpy="1.57079632679 0 1.57079632679" xyz="0 0 0"/>
      <inertia ixx="2.34375e-06" ixy="0" ixz="0" iyy="2.08333333333e-07" iyz="0" izz="2.40208333333e-06"/>
    </inertial>
  </link>
  <joint name="robot_front_rgbd_camera_depth_joint" type="fixed">
    <origin rpy="0 0 0" xyz="0.0 0.0375 0.0150"/>
    <parent link="robot_front_rgbd_camera_link"/>
    <child link="robot_front_rgbd_camera_depth_frame"/>
  </joint>
  <link name="robot_front_rgbd_camera_depth_frame">
    <inertial>
      <mass value="0.001"/>
      <origin xyz="0 0 0"/>
      <inertia ixx="2.34375e-06" ixy="0" ixz="0" iyy="2.08333333333e-07" iyz="0" izz="2.40208333333e-06"/>
    </inertial>
  </link>
  <joint name="robot_front_rgbd_camera_depth_optical_joint" type="fixed">
    <origin rpy="-1.57079632679 0 -1.57079632679" xyz="0 0 0.07"/>
    <parent link="robot_front_rgbd_camera_depth_frame"/>
    <child link="robot_front_rgbd_camera_depth_optical_frame"/>
  </joint>
  <link name="robot_front_rgbd_camera_depth_optical_frame">
    <inertial>
      <mass value="0.001"/>
      <origin xyz="0 0 0"/>
      <inertia ixx="2.34375e-06" ixy="0" ixz="0" iyy="2.08333333333e-07" iyz="0" izz="2.40208333333e-06"/>
    </inertial>
  </link>
  <gazebo reference="robot_front_rgbd_camera_link">
    <sensor name="robot_front_rgbd_camera_depth_sensor" type="depth">
      <always_on>true</always_on>
      <update_rate>20.0</update_rate>
      <camera>
        <horizontal_fov>1.0471975512</horizontal_fov>
        <image>
          <format>R8G8B8</format>
          <width>640</width>
          <height>480</height>
        </image>
        <clip>
          <near>0.05</near>
          <far>3.5</far>
        </clip>
      </camera>
      <plugin filename="libgazebo_ros_openni_kinect.so" name="robot_front_rgbd_camera_controller">
        <cameraName>front_rgbd_camera</cameraName>
        <alwaysOn>true</alwaysOn>
        <updateRate>10</updateRate>
        <imageTopicName>rgb/image_raw</imageTopicName>
        <depthImageTopicName>depth/image_raw</depthImageTopicName>
        <pointCloudTopicName>depth/points</pointCloudTopicName>
        <cameraInfoTopicName>rgb/camera_info</cameraInfoTopicName>
        <depthImageCameraInfoTopicName>depth/camera_info</depthImageCameraInfoTopicName>
        <frameName>/robot_front_rgbd_camera_depth_optical_frame</frameName>
        <baseline>0.1</baseline>
        <distortion_k1>0.0</distortion_k1>
        <distortion_k2>0.0</distortion_k2>
        <distortion_k3>0.0</distortion_k3>
        <distortion_t1>0.0</distortion_t1>
        <distortion_t2>0.0</distortion_t2>
        <pointCloudCutoff>0.4</pointCloudCutoff>
      </plugin>
    </sensor>
  </gazebo>
  <joint name="robot_gripper_base_joint" type="fixed">
    <origin rpy="0 -1.57 0" xyz="0.0 0.0 0.0"/>
    <parent link="robot_arm_tool0"/>
    <child link="robot_gripper_base_link"/>
  </joint>
  <!-- BASE LINK -->
  <link name="robot_gripper_base_link">
    <inertial>
      <mass value="0.25"/>
      <origin xyz="0 0 0"/>
      <inertia ixx="1.0" ixy="0.0" ixz="0.0" iyy="1.0" iyz="0.0" izz="1.0"/>
    </inertial>
    <visual>
      <origin rpy="0.0 0.0 0.0" xyz="0.0 0.0 0.0"/>
      <geometry>
        <mesh filename="package://egh_gripper_description/meshes/egh_base.stl" scale="1 1 1"/>
      </geometry>
      <material name="grey">
        <color rgba="0.5 0.5 0.5 1"/>
      </material>
    </visual>
    <collision>
      <origin rpy="0 0 0" xyz="0.0 0 0"/>
      <geometry>
        <!--box size="0.146 0.05 0.0735"/-->
        <mesh filename="package://egh_gripper_description/meshes/egh_base.stl" scale="1 1 1"/>
      </geometry>
    </collision>
  </link>
  <gazebo reference="robot_gripper_base_link">
    <material>Gazebo/Grey</material>
    <turnGravityOff>false</turnGravityOff>
  </gazebo>
  <!-- FINGER LEFT -->
  <joint name="robot_gripper_finger_left_joint" type="prismatic">
    <limit effort="1.0" lower="0.0" upper="0.048" velocity="0.0125"/>
    <axis xyz="0 -1 0"/>
    <origin rpy="0.0 0.0 0.0" xyz="0.11 -0.013 0"/>
    <parent link="robot_gripper_base_link"/>
    <child link="robot_gripper_left_finger"/>
    <dynamics damping="100" friction="100"/>
  </joint>
  <transmission name="robot_gripper_base_trans_left">
    <type>transmission_interface/SimpleTransmission</type>
    <actuator name="robot_gripper_base_motor_left">
      <mechanicalReduction>1</mechanicalReduction>
      <motorTorqueConstant>1</motorTorqueConstant>
    </actuator>
    <joint name="robot_gripper_finger_left_joint">
      <hardwareInterface>hardware_interface/PositionJointInterface</hardwareInterface>
    </joint>
  </transmission>
  <link name="robot_gripper_left_finger">
    <inertial>
      <mass value="0.1"/>
      <origin xyz="0 0 0"/>
      <inertia ixx="1.0" ixy="0.0" ixz="0.0" iyy="1.0" iyz="0.0" izz="1.0"/>
    </inertial>
    <visual>
      <origin rpy="3.14159265359 0 0" xyz="0.0 0 0"/>
      <geometry>
        <mesh filename="package://egh_gripper_description/meshes/egh_finger.stl" scale="1.0 1.0 1.0"/>
      </geometry>
      <material name="black">
        <color rgba="0 0 0 0"/>
      </material>
    </visual>
    <collision>
      <origin rpy="3.14159265359 0 0" xyz="0 0 0"/>
      <geometry>
        <mesh filename="package://egh_gripper_description/meshes/egh_finger.stl" scale="1.0 1.0 1.0"/>
      </geometry>
    </collision>
    <contact_coefficients kd="1.0" kp="1000.0" mu="0"/>
  </link>
  <gazebo reference="robot_gripper_left_finger">
    <material>Gazebo/Blue</material>
    <turnGravityOff>false</turnGravityOff>
  </gazebo>
  <!-- FINGER RIGHT -->
  <joint name="robot_gripper_finger_right_joint" type="prismatic">
    <limit effort="1.0" lower="0.0" upper="0.048" velocity="0.0125"/>
    <axis xyz="0 1 0"/>
    <origin rpy="0 0 0" xyz="0.11 0.013 0"/>
    <parent link="robot_gripper_base_link"/>
    <child link="robot_gripper_right_finger"/>
    <dynamics damping="100" friction="100"/>
    <mimic joint="robot_gripper_finger_left_joint" multiplier="1" offset="0"/>
  </joint>
  <!-- 
            The transmission is not defined cause the right finger is mirroring
            the left finger using mimic plugin
        -->
  <!--transmission name="${prefix}_base_trans_right">
            <type>transmission_interface/SimpleTransmission</type>
            <actuator name="${prefix}_base_motor_right">
                <mechanicalReduction>1</mechanicalReduction>
                <motorTorqueConstant>1</motorTorqueConstant>
            </actuator>
            <joint name="${prefix}_finger_right_joint" >
                <hardwareInterface>hardware_interface/PositionJointInterface</hardwareInterface>
            </joint>
        </transmission-->
  <gazebo>
    <plugin filename="libroboticsgroup_gazebo_mimic_joint_plugin.so" name="robot_gripper_finger_right_joint_mimic_joint_plugin">
      <joint>robot_gripper_finger_left_joint</joint>
      <mimicJoint>robot_gripper_finger_right_joint</mimicJoint>
      <multiplier>1.0</multiplier>
      <offset>0</offset>
      <sensitiveness>0.0</sensitiveness>
      <maxEffort>10.0</maxEffort>
    </plugin>
  </gazebo>
  <link name="robot_gripper_right_finger">
    <inertial>
      <mass value="0.1"/>
      <origin xyz="0 0 0"/>
      <inertia ixx="1.0" ixy="0.0" ixz="0.0" iyy="1.0" iyz="0.0" izz="1.0"/>
    </inertial>
    <visual>
      <origin rpy="0 0 0" xyz="0.0 0 0"/>
      <geometry>
        <mesh filename="package://egh_gripper_description/meshes/egh_finger.stl" scale="1.0 1.0 1.0"/>
      </geometry>
      <material name="black">
        <color rgba="0 0 0 0"/>
      </material>
    </visual>
    <collision>
      <origin rpy="0 0 0" xyz="0 0 0"/>
      <geometry>
        <mesh filename="package://egh_gripper_description/meshes/egh_finger.stl" scale="1.0 1.0 1.0"/>
      </geometry>
    </collision>
    <contact_coefficients kd="1.0" kp="1000.0" mu="0"/>
  </link>
  <gazebo reference="robot_gripper_right_finger">
    <material>Gazebo/Blue</material>
    <turnGravityOff>false</turnGravityOff>
  </gazebo>
  <!--xacro:sensor_zed prefix="$(arg prefix)front_rgbd_camera" parent="$(arg prefix)base_link" prefix_topic="front_rgbd_camera">
  			<origin xyz="${front_rgbd_camera_offset_x} ${front_rgbd_camera_offset_y} ${front_rgbd_camera_offset_z}" rpy="0 0 0"/>
  		</xacro:sensor_zed-->
</robot>

